{
	"documenttitle": {
		"text": "Red Hat Security Advisory: python security, bug fix, and enhancement update",
		"lang": "en"
	},
	"DocumentType": "Security Advisory",
	"documentpublisher": {
		"type": "Vendor",
		"ContactDetails": "secalert@redhat.com",
		"IssuingAuthority": "Red Hat Product Security"
	},
	"documenttracking": {
		"identification": {
			"ID": "RHSA-2011:0027"
		},
		"Status": "Final",
		"Version": "1",
		"revisionhistory": {
			"revision": {
				"Number": "1",
				"Date": "2011-01-13T05:58:00Z",
				"Description": "Current version"
			}
		},
		"InitialReleaseDate": "2011-01-13T10:55:00Z",
		"CurrentReleaseDate": "2011-01-13T05:58:00Z",
		"generator": {
			"Engine": "Red Hat SDEngine 3.0.0",
			"Date": "2021-08-23T04:37:00Z"
		}
	},
	"documentnotes": {
		"note": [
			{
				"text": "\nUpdated python packages that fix multiple security issues, several bugs,\nand add two enhancements are now available for Red Hat Enterprise Linux 5.\n\nThe Red Hat Security Response Team has rated this update as having low\nsecurity impact. Common Vulnerability Scoring System (CVSS) base scores,\nwhich give detailed severity ratings, are available for each vulnerability\nfrom the CVE links in the References section.\n    ",
				"title": "Topic",
				"type": "Summary",
				"ordinal": "1",
				"lang": "en"
			},
			{
				"text": "\nPython is an interpreted, interactive, object-oriented programming\nlanguage.\n\nIt was found that many applications embedding the Python interpreter did\nnot specify a valid full path to the script or application when calling the\nPySys_SetArgv API function, which could result in the addition of the\ncurrent working directory to the module search path (sys.path). A local\nattacker able to trick a victim into running such an application in an\nattacker-controlled directory could use this flaw to execute code with the\nvictim's privileges. This update adds the PySys_SetArgvEx API. Developers\ncan modify their applications to use this new API, which sets sys.argv\nwithout modifying sys.path. (CVE-2008-5983)\n\nMultiple flaws were found in the Python rgbimg module. If an application\nwritten in Python was using the rgbimg module and loaded a\nspecially-crafted SGI image file, it could cause the application to crash\nor, possibly, execute arbitrary code with the privileges of the user\nrunning the application. (CVE-2009-4134, CVE-2010-1449, CVE-2010-1450)\n\nMultiple flaws were found in the Python audioop module. Supplying certain\ninputs could cause the audioop module to crash or, possibly, execute\narbitrary code. (CVE-2010-1634, CVE-2010-2089)\n\nThis update also fixes the following bugs:\n\n* When starting a child process from the subprocess module in Python 2.4,\nthe parent process could leak file descriptors if an error occurred. This\nupdate resolves the issue. (BZ#609017)\n\n* Prior to Python 2.7, programs that used \"ulimit -n\" to enable\ncommunication with large numbers of subprocesses could still monitor only\n1024 file descriptors at a time, which caused an exception:\n\n  ValueError: filedescriptor out of range in select()\n\nThis was due to the subprocess module using the \"select\" system call. The\nmodule now uses the \"poll\" system call, removing this limitation.\n(BZ#609020)\n\n* Prior to Python 2.5, the tarfile module failed to unpack tar files if the\npath was longer than 100 characters. This update backports the tarfile\nmodule from Python 2.5 and the issue no longer occurs. (BZ#263401)\n\n* The email module incorrectly implemented the logic for obtaining\nattachment file names: the get_filename() fallback for using the deprecated\n\"name\" parameter of the \"Content-Type\" header erroneously used the\n\"Content-Disposition\" header. This update backports a fix from Python 2.6,\nwhich resolves this issue. (BZ#644147)\n\n* Prior to version 2.5, Python's optimized memory allocator never released\nmemory back to the system. The memory usage of a long-running Python\nprocess would resemble a \"high-water mark\". This update backports a fix\nfrom Python 2.5a1, which frees unused arenas, and adds a non-standard\nsys._debugmallocstats() function, which prints diagnostic information to\nstderr. Finally, when running under Valgrind, the optimized allocator is\ndeactivated, to allow more convenient debugging of Python memory usage\nissues. (BZ#569093)\n\n* The urllib and urllib2 modules ignored the no_proxy variable, which could\nlead to programs such as \"yum\" erroneously accessing a proxy server for\nURLs covered by a \"no_proxy\" exclusion. This update backports fixes of\nurllib and urllib2, which respect the \"no_proxy\" variable, which fixes\nthese issues. (BZ#549372)\n\nAs well, this update adds the following enhancements:\n\n* This update introduces a new python-libs package, subsuming the majority\nof the content of the core python package. This makes both 32-bit and\n64-bit Python libraries available on PowerPC systems. (BZ#625372)\n\n* The python-libs.i386 package is now available for 64-bit Itanium with the\n32-bit Itanium compatibility mode. (BZ#644761)\n\nAll Python users are advised to upgrade to these updated packages, which\ncontain backported patches to correct these issues and add these\nenhancements.\n    ",
				"title": "Details",
				"type": "General",
				"ordinal": "2",
				"lang": "en"
			},
			{
				"text": "This content is licensed under the Creative Commons Attribution 4.0 International License (https://creativecommons.org/licenses/by/4.0/). If you distribute this content, or a modified version of it, you must provide attribution to Red Hat Inc. and provide a link to the original.",
				"title": "Terms of Use",
				"type": "Legal Disclaimer",
				"ordinal": "3",
				"lang": "en"
			}
		]
	},
	"documentdistribution": {
		"text": "Copyright Â© 2021 Red Hat, Inc. All rights reserved.",
		"lang": "en"
	},
	"aggregateseverity": {
		"text": "Low",
		"namespace": "https://access.redhat.com/security/updates/classification/"
	},
	"documentreferences": {
		"reference": [
			{
				"type": "Self",
				"URL": "https://access.redhat.com/errata/RHSA-2011:0027",
				"Description": "https://access.redhat.com/errata/RHSA-2011:0027"
			},
			{
				"type": "External",
				"URL": "https://access.redhat.com/security/updates/classification/#low",
				"Description": "https://access.redhat.com/security/updates/classification/#low"
			}
		]
	},
	"vulnerability": [
		{
			"ordinal": "1",
			"xmlns": "http://www.icasi.org/CVRF/schema/vuln/1.1",
			"notes": {
				"note": {
					"text": "python: untrusted python modules search path",
					"title": "Vulnerability Description",
					"type": "General",
					"ordinal": "1",
					"lang": "en"
				}
			},
			"ReleaseDate": "2008-08-06T00:00:00Z",
			"involvements": {
				"involvement": {
					"party": "Vendor",
					"status": "Completed"
				}
			},
			"CVE": "CVE-2008-5983",
			"remediations": {
				"remediation": {
					"type": "Vendor Fix",
					"description": {
						"text": "\nBefore applying this update, make sure all previously-released errata\nrelevant to your system have been applied.\n\nThis update is available via the Red Hat Network. Details on how to\nuse the Red Hat Network to apply this update are available at\nhttp://kbase.redhat.com/faq/docs/DOC-11259\n    ",
						"lang": "en"
					},
					"URL": "https://access.redhat.com/errata/RHSA-2011:0027"
				}
			},
			"references": {
				"reference": [
					{
						"URL": "https://access.redhat.com/security/cve/CVE-2008-5983",
						"Description": "CVE-2008-5983"
					},
					{
						"URL": "https://bugzilla.redhat.com/show_bug.cgi?id=482814",
						"Description": "bz#482814: CVE-2008-5983 python: untrusted python modules search path"
					}
				]
			},
			"threats": {
				"threat": {
					"type": "Impact",
					"Description": "Low"
				}
			},
			"DiscoveryDate": "2008-11-03T00:00:00Z",
			"productstatuses": {
				"status": {
					"type": "Fixed",
					"ProductID": [
						"5Client-Workstation:python-0:2.4.3-43.el5",
						"5Client:python-0:2.4.3-43.el5",
						"5Server:python-0:2.4.3-43.el5"
					]
				}
			},
			"acknowledgments": {
				"acknowledgment": {
					"Description": ""
				}
			},
			"cvssscoresets": {
				"scoreset": {
					"BaseScore": "3.7",
					"Vector": "AV:L/AC:H/Au:N/C:P/I:P/A:P"
				}
			}
		},
		{
			"ordinal": "2",
			"xmlns": "http://www.icasi.org/CVRF/schema/vuln/1.1",
			"notes": {
				"note": {
					"text": "python: rgbimg: multiple security issues",
					"title": "Vulnerability Description",
					"type": "General",
					"ordinal": "1",
					"lang": "en"
				}
			},
			"ReleaseDate": "2010-05-10T00:00:00Z",
			"involvements": {
				"involvement": {
					"party": "Vendor",
					"status": "Completed"
				}
			},
			"CVE": "CVE-2009-4134",
			"remediations": {
				"remediation": {
					"type": "Vendor Fix",
					"description": {
						"text": "\nBefore applying this update, make sure all previously-released errata\nrelevant to your system have been applied.\n\nThis update is available via the Red Hat Network. Details on how to\nuse the Red Hat Network to apply this update are available at\nhttp://kbase.redhat.com/faq/docs/DOC-11259\n    ",
						"lang": "en"
					},
					"URL": "https://access.redhat.com/errata/RHSA-2011:0027"
				}
			},
			"references": {
				"reference": [
					{
						"URL": "https://access.redhat.com/security/cve/CVE-2009-4134",
						"Description": "CVE-2009-4134"
					},
					{
						"URL": "https://bugzilla.redhat.com/show_bug.cgi?id=541698",
						"Description": "bz#541698: CVE-2009-4134 CVE-2010-1449 CVE-2010-1450 python: rgbimg: multiple security issues"
					}
				]
			},
			"threats": {
				"threat": {
					"type": "Impact",
					"Description": "Low"
				}
			},
			"DiscoveryDate": "2009-11-26T00:00:00Z",
			"productstatuses": {
				"status": {
					"type": "Fixed",
					"ProductID": [
						"5Client-Workstation:python-0:2.4.3-43.el5",
						"5Client:python-0:2.4.3-43.el5",
						"5Server:python-0:2.4.3-43.el5"
					]
				}
			},
			"acknowledgments": {
				"acknowledgment": {
					"Description": ""
				}
			},
			"cvssscoresets": {
				"scoreset": {
					"BaseScore": "5.1",
					"Vector": "AV:N/AC:H/Au:N/C:P/I:P/A:P"
				}
			}
		},
		{
			"ordinal": "3",
			"xmlns": "http://www.icasi.org/CVRF/schema/vuln/1.1",
			"notes": {
				"note": {
					"text": "python: rgbimg: multiple security issues",
					"title": "Vulnerability Description",
					"type": "General",
					"ordinal": "1",
					"lang": "en"
				}
			},
			"ReleaseDate": "2010-05-10T00:00:00Z",
			"involvements": {
				"involvement": {
					"party": "Vendor",
					"status": "Completed"
				}
			},
			"CVE": "CVE-2010-1449",
			"remediations": {
				"remediation": {
					"type": "Vendor Fix",
					"description": {
						"text": "\nBefore applying this update, make sure all previously-released errata\nrelevant to your system have been applied.\n\nThis update is available via the Red Hat Network. Details on how to\nuse the Red Hat Network to apply this update are available at\nhttp://kbase.redhat.com/faq/docs/DOC-11259\n    ",
						"lang": "en"
					},
					"URL": "https://access.redhat.com/errata/RHSA-2011:0027"
				}
			},
			"references": {
				"reference": [
					{
						"URL": "https://access.redhat.com/security/cve/CVE-2010-1449",
						"Description": "CVE-2010-1449"
					},
					{
						"URL": "https://bugzilla.redhat.com/show_bug.cgi?id=541698",
						"Description": "bz#541698: CVE-2009-4134 CVE-2010-1449 CVE-2010-1450 python: rgbimg: multiple security issues"
					}
				]
			},
			"threats": {
				"threat": {
					"type": "Impact",
					"Description": "Low"
				}
			},
			"DiscoveryDate": "2009-11-26T00:00:00Z",
			"productstatuses": {
				"status": {
					"type": "Fixed",
					"ProductID": [
						"5Client-Workstation:python-0:2.4.3-43.el5",
						"5Client:python-0:2.4.3-43.el5",
						"5Server:python-0:2.4.3-43.el5"
					]
				}
			},
			"acknowledgments": {
				"acknowledgment": {
					"Description": ""
				}
			},
			"cvssscoresets": {
				"scoreset": {
					"BaseScore": "5.1",
					"Vector": "AV:N/AC:H/Au:N/C:P/I:P/A:P"
				}
			}
		},
		{
			"ordinal": "4",
			"xmlns": "http://www.icasi.org/CVRF/schema/vuln/1.1",
			"notes": {
				"note": {
					"text": "python: rgbimg: multiple security issues",
					"title": "Vulnerability Description",
					"type": "General",
					"ordinal": "1",
					"lang": "en"
				}
			},
			"ReleaseDate": "2010-05-10T00:00:00Z",
			"involvements": {
				"involvement": {
					"party": "Vendor",
					"status": "Completed"
				}
			},
			"CVE": "CVE-2010-1450",
			"remediations": {
				"remediation": {
					"type": "Vendor Fix",
					"description": {
						"text": "\nBefore applying this update, make sure all previously-released errata\nrelevant to your system have been applied.\n\nThis update is available via the Red Hat Network. Details on how to\nuse the Red Hat Network to apply this update are available at\nhttp://kbase.redhat.com/faq/docs/DOC-11259\n    ",
						"lang": "en"
					},
					"URL": "https://access.redhat.com/errata/RHSA-2011:0027"
				}
			},
			"references": {
				"reference": [
					{
						"URL": "https://access.redhat.com/security/cve/CVE-2010-1450",
						"Description": "CVE-2010-1450"
					},
					{
						"URL": "https://bugzilla.redhat.com/show_bug.cgi?id=541698",
						"Description": "bz#541698: CVE-2009-4134 CVE-2010-1449 CVE-2010-1450 python: rgbimg: multiple security issues"
					}
				]
			},
			"threats": {
				"threat": {
					"type": "Impact",
					"Description": "Low"
				}
			},
			"DiscoveryDate": "2009-11-26T00:00:00Z",
			"productstatuses": {
				"status": {
					"type": "Fixed",
					"ProductID": [
						"5Client-Workstation:python-0:2.4.3-43.el5",
						"5Client:python-0:2.4.3-43.el5",
						"5Server:python-0:2.4.3-43.el5"
					]
				}
			},
			"acknowledgments": {
				"acknowledgment": {
					"Description": ""
				}
			},
			"cvssscoresets": {
				"scoreset": {
					"BaseScore": "5.1",
					"Vector": "AV:N/AC:H/Au:N/C:P/I:P/A:P"
				}
			}
		},
		{
			"ordinal": "5",
			"xmlns": "http://www.icasi.org/CVRF/schema/vuln/1.1",
			"notes": {
				"note": {
					"text": "python: audioop: incorrect integer overflow checks",
					"title": "Vulnerability Description",
					"type": "General",
					"ordinal": "1",
					"lang": "en"
				}
			},
			"ReleaseDate": "2010-05-10T00:00:00Z",
			"involvements": {
				"involvement": {
					"party": "Vendor",
					"status": "Completed"
				}
			},
			"CVE": "CVE-2010-1634",
			"remediations": {
				"remediation": {
					"type": "Vendor Fix",
					"description": {
						"text": "\nBefore applying this update, make sure all previously-released errata\nrelevant to your system have been applied.\n\nThis update is available via the Red Hat Network. Details on how to\nuse the Red Hat Network to apply this update are available at\nhttp://kbase.redhat.com/faq/docs/DOC-11259\n    ",
						"lang": "en"
					},
					"URL": "https://access.redhat.com/errata/RHSA-2011:0027"
				}
			},
			"references": {
				"reference": [
					{
						"URL": "https://access.redhat.com/security/cve/CVE-2010-1634",
						"Description": "CVE-2010-1634"
					},
					{
						"URL": "https://bugzilla.redhat.com/show_bug.cgi?id=590690",
						"Description": "bz#590690: CVE-2010-1634 python: audioop: incorrect integer overflow checks"
					}
				]
			},
			"threats": {
				"threat": {
					"type": "Impact",
					"Description": "Low"
				}
			},
			"DiscoveryDate": "2009-11-26T00:00:00Z",
			"productstatuses": {
				"status": {
					"type": "Fixed",
					"ProductID": [
						"5Client-Workstation:python-0:2.4.3-43.el5",
						"5Client:python-0:2.4.3-43.el5",
						"5Server:python-0:2.4.3-43.el5"
					]
				}
			},
			"acknowledgments": {
				"acknowledgment": {
					"Description": ""
				}
			},
			"cvssscoresets": {
				"scoreset": {
					"BaseScore": "5.1",
					"Vector": "AV:N/AC:H/Au:N/C:P/I:P/A:P"
				}
			}
		},
		{
			"ordinal": "6",
			"xmlns": "http://www.icasi.org/CVRF/schema/vuln/1.1",
			"notes": {
				"note": {
					"text": "Python: Memory corruption in audioop module",
					"title": "Vulnerability Description",
					"type": "General",
					"ordinal": "1",
					"lang": "en"
				}
			},
			"ReleaseDate": "2010-01-11T00:00:00Z",
			"involvements": {
				"involvement": {
					"party": "Vendor",
					"status": "Completed"
				}
			},
			"CVE": "CVE-2010-2089",
			"remediations": {
				"remediation": {
					"type": "Vendor Fix",
					"description": {
						"text": "\nBefore applying this update, make sure all previously-released errata\nrelevant to your system have been applied.\n\nThis update is available via the Red Hat Network. Details on how to\nuse the Red Hat Network to apply this update are available at\nhttp://kbase.redhat.com/faq/docs/DOC-11259\n    ",
						"lang": "en"
					},
					"URL": "https://access.redhat.com/errata/RHSA-2011:0027"
				}
			},
			"references": {
				"reference": [
					{
						"URL": "https://access.redhat.com/security/cve/CVE-2010-2089",
						"Description": "CVE-2010-2089"
					},
					{
						"URL": "https://bugzilla.redhat.com/show_bug.cgi?id=598197",
						"Description": "bz#598197: CVE-2010-2089 Python: Memory corruption in audioop module"
					}
				]
			},
			"threats": {
				"threat": {
					"type": "Impact",
					"Description": "Low"
				}
			},
			"DiscoveryDate": "2010-05-27T00:00:00Z",
			"productstatuses": {
				"status": {
					"type": "Fixed",
					"ProductID": [
						"5Client-Workstation:python-0:2.4.3-43.el5",
						"5Client:python-0:2.4.3-43.el5",
						"5Server:python-0:2.4.3-43.el5"
					]
				}
			},
			"acknowledgments": {
				"acknowledgment": {
					"Description": ""
				}
			},
			"cvssscoresets": {
				"scoreset": {
					"BaseScore": "4.3",
					"Vector": "AV:N/AC:M/Au:N/C:N/I:N/A:P"
				}
			}
		}
	],
	"producttree": {
		"xmlns": "http://www.icasi.org/CVRF/schema/prod/1.1",
		"branch": [
			{
				"type": "Product Family",
				"name": "Red Hat Enterprise Linux",
				"branch": [
					{
						"type": "Product Name",
						"name": "Red Hat Enterprise Linux Desktop (v. 5 client)",
						"fullproductname": {
							"text": "Red Hat Enterprise Linux Desktop (v. 5 client)",
							"productid": "5Client",
							"cpe": "cpe:/o:redhat:enterprise_linux:5::client"
						}
					},
					{
						"type": "Product Name",
						"name": "Red Hat Enterprise Linux Desktop Workstation (v. 5 client)",
						"fullproductname": {
							"text": "Red Hat Enterprise Linux Desktop Workstation (v. 5 client)",
							"productid": "5Client-Workstation",
							"cpe": "cpe:/o:redhat:enterprise_linux:5::client_workstation"
						}
					},
					{
						"type": "Product Name",
						"name": "Red Hat Enterprise Linux (v. 5 server)",
						"fullproductname": {
							"text": "Red Hat Enterprise Linux (v. 5 server)",
							"productid": "5Server",
							"cpe": "cpe:/o:redhat:enterprise_linux:5::server"
						}
					}
				],
				"fullproductname": {}
			},
			{
				"type": "Product Version",
				"name": "python-0:2.4.3-43.el5",
				"fullproductname": {
					"text": "python-2.4.3-43.el5.src.rpm",
					"productid": "python-0:2.4.3-43.el5",
					"cpe": "cpe:/o:redhat:enterprise_linux:5::client"
				}
			}
		],
		"relationship": [
			{
				"productreference": "python-0:2.4.3-43.el5",
				"relationtype": "Default Component Of",
				"relatestoproductreference": "5Client",
				"fullproductname": {
					"text": "python-0:2.4.3-43.el5 as a component of Red Hat Enterprise Linux Desktop (v. 5 client)",
					"productid": "5Client:python-0:2.4.3-43.el5",
					"cpe": "cpe:/o:redhat:enterprise_linux:5::client"
				}
			},
			{
				"productreference": "python-0:2.4.3-43.el5",
				"relationtype": "Default Component Of",
				"relatestoproductreference": "5Client-Workstation",
				"fullproductname": {
					"text": "python-0:2.4.3-43.el5 as a component of Red Hat Enterprise Linux Desktop Workstation (v. 5 client)",
					"productid": "5Client-Workstation:python-0:2.4.3-43.el5",
					"cpe": "cpe:/o:redhat:enterprise_linux:5::client_workstation"
				}
			},
			{
				"productreference": "python-0:2.4.3-43.el5",
				"relationtype": "Default Component Of",
				"relatestoproductreference": "5Server",
				"fullproductname": {
					"text": "python-0:2.4.3-43.el5 as a component of Red Hat Enterprise Linux (v. 5 server)",
					"productid": "5Server:python-0:2.4.3-43.el5",
					"cpe": "cpe:/o:redhat:enterprise_linux:5::server"
				}
			}
		]
	}
}
